2021-09-06 21:37:22,818 WARNING  * Running on all addresses.
   WARNING: This is a development server. Do not use it in a production deployment.
2021-09-06 21:37:22,826 INFO  * Running on http://192.168.43.247:3111/ (Press CTRL+C to quit)
2021-09-06 21:38:05,681 INFO 127.0.0.1 - - [06/Sep/2021 21:38:05] "GET / HTTP/1.1" 200 -
2021-09-06 21:38:05,790 INFO 127.0.0.1 - - [06/Sep/2021 21:38:05] "GET /static/css/main.css HTTP/1.1" 200 -
2021-09-06 21:38:05,995 INFO 127.0.0.1 - - [06/Sep/2021 21:38:05] "[33mGET /favicon.ico HTTP/1.1[0m" 404 -
2021-09-06 21:38:18,389 INFO KubeCon + CloudNativeCon 2021
2021-09-06 21:38:18,425 INFO 127.0.0.1 - - [06/Sep/2021 21:38:18] "GET /2 HTTP/1.1" 200 -
2021-09-06 21:38:18,592 INFO 127.0.0.1 - - [06/Sep/2021 21:38:18] "[36mGET /static/css/main.css HTTP/1.1[0m" 304 -
2021-09-06 21:38:22,957 INFO About us page is retrieved
2021-09-06 21:38:22,969 INFO 127.0.0.1 - - [06/Sep/2021 21:38:22] "GET /about HTTP/1.1" 200 -
2021-09-06 21:38:23,284 INFO 127.0.0.1 - - [06/Sep/2021 21:38:23] "[36mGET /static/css/main.css HTTP/1.1[0m" 304 -
2021-09-06 21:38:26,989 INFO 127.0.0.1 - - [06/Sep/2021 21:38:26] "GET /create HTTP/1.1" 200 -
2021-09-06 21:38:27,080 INFO 127.0.0.1 - - [06/Sep/2021 21:38:27] "[36mGET /static/css/main.css HTTP/1.1[0m" 304 -
2021-09-06 21:38:44,698 INFO A new article is created
2021-09-06 21:38:44,700 INFO 127.0.0.1 - - [06/Sep/2021 21:38:44] "[32mPOST /create HTTP/1.1[0m" 302 -
2021-09-06 21:38:44,826 INFO 127.0.0.1 - - [06/Sep/2021 21:38:44] "GET / HTTP/1.1" 200 -
2021-09-06 21:38:45,168 INFO 127.0.0.1 - - [06/Sep/2021 21:38:45] "[36mGET /static/css/main.css HTTP/1.1[0m" 304 -
2021-09-06 21:38:57,707 ERROR Exception on /metrics [GET]
Traceback (most recent call last):
  File "C:\Users\neo\AppData\Local\Programs\Python\Python36\lib\site-packages\flask\app.py", line 2070, in wsgi_app
    response = self.full_dispatch_request()
  File "C:\Users\neo\AppData\Local\Programs\Python\Python36\lib\site-packages\flask\app.py", line 1515, in full_dispatch_request
    rv = self.handle_user_exception(e)
  File "C:\Users\neo\AppData\Local\Programs\Python\Python36\lib\site-packages\flask\app.py", line 1513, in full_dispatch_request
    rv = self.dispatch_request()
  File "C:\Users\neo\AppData\Local\Programs\Python\Python36\lib\site-packages\flask\app.py", line 1499, in dispatch_request
    return self.ensure_sync(self.view_functions[rule.endpoint])(**req.view_args)
  File "app.py", line 110, in metrics
    response=json.dumps(data),
  File "C:\Users\neo\AppData\Local\Programs\Python\Python36\lib\site-packages\flask\json\__init__.py", line 129, in dumps
    rv = _json.dumps(obj, **kwargs)
  File "C:\Users\neo\AppData\Local\Programs\Python\Python36\lib\json\__init__.py", line 238, in dumps
    **kw).encode(obj)
  File "C:\Users\neo\AppData\Local\Programs\Python\Python36\lib\json\encoder.py", line 199, in encode
    chunks = self.iterencode(o, _one_shot=True)
  File "C:\Users\neo\AppData\Local\Programs\Python\Python36\lib\json\encoder.py", line 257, in iterencode
    return _iterencode(o, 0)
  File "C:\Users\neo\AppData\Local\Programs\Python\Python36\lib\site-packages\flask\json\__init__.py", line 56, in default
    return super().default(o)
  File "C:\Users\neo\AppData\Local\Programs\Python\Python36\lib\json\encoder.py", line 180, in default
    o.__class__.__name__)
TypeError: Object of type 'Row' is not JSON serializable
2021-09-06 21:38:58,153 INFO 127.0.0.1 - - [06/Sep/2021 21:38:58] "[35m[1mGET /metrics HTTP/1.1[0m" 500 -
2021-09-06 21:39:04,647 INFO 127.0.0.1 - - [06/Sep/2021 21:39:04] "[33mGET /metricz HTTP/1.1[0m" 404 -
2021-09-06 21:40:24,531 ERROR Exception on /metrics [GET]
Traceback (most recent call last):
  File "C:\Users\neo\AppData\Local\Programs\Python\Python36\lib\site-packages\flask\app.py", line 2070, in wsgi_app
    response = self.full_dispatch_request()
  File "C:\Users\neo\AppData\Local\Programs\Python\Python36\lib\site-packages\flask\app.py", line 1515, in full_dispatch_request
    rv = self.handle_user_exception(e)
  File "C:\Users\neo\AppData\Local\Programs\Python\Python36\lib\site-packages\flask\app.py", line 1513, in full_dispatch_request
    rv = self.dispatch_request()
  File "C:\Users\neo\AppData\Local\Programs\Python\Python36\lib\site-packages\flask\app.py", line 1499, in dispatch_request
    return self.ensure_sync(self.view_functions[rule.endpoint])(**req.view_args)
  File "app.py", line 110, in metrics
    response=json.dumps(data),
  File "C:\Users\neo\AppData\Local\Programs\Python\Python36\lib\site-packages\flask\json\__init__.py", line 129, in dumps
    rv = _json.dumps(obj, **kwargs)
  File "C:\Users\neo\AppData\Local\Programs\Python\Python36\lib\json\__init__.py", line 238, in dumps
    **kw).encode(obj)
  File "C:\Users\neo\AppData\Local\Programs\Python\Python36\lib\json\encoder.py", line 199, in encode
    chunks = self.iterencode(o, _one_shot=True)
  File "C:\Users\neo\AppData\Local\Programs\Python\Python36\lib\json\encoder.py", line 257, in iterencode
    return _iterencode(o, 0)
  File "C:\Users\neo\AppData\Local\Programs\Python\Python36\lib\site-packages\flask\json\__init__.py", line 56, in default
    return super().default(o)
  File "C:\Users\neo\AppData\Local\Programs\Python\Python36\lib\json\encoder.py", line 180, in default
    o.__class__.__name__)
TypeError: Object of type 'Row' is not JSON serializable
2021-09-06 21:40:24,536 INFO 127.0.0.1 - - [06/Sep/2021 21:40:24] "[35m[1mGET /metrics HTTP/1.1[0m" 500 -
2021-09-06 21:47:38,820 ERROR Exception on /metrics [GET]
Traceback (most recent call last):
  File "C:\Users\neo\AppData\Local\Programs\Python\Python36\lib\site-packages\flask\app.py", line 2070, in wsgi_app
    response = self.full_dispatch_request()
  File "C:\Users\neo\AppData\Local\Programs\Python\Python36\lib\site-packages\flask\app.py", line 1515, in full_dispatch_request
    rv = self.handle_user_exception(e)
  File "C:\Users\neo\AppData\Local\Programs\Python\Python36\lib\site-packages\flask\app.py", line 1513, in full_dispatch_request
    rv = self.dispatch_request()
  File "C:\Users\neo\AppData\Local\Programs\Python\Python36\lib\site-packages\flask\app.py", line 1499, in dispatch_request
    return self.ensure_sync(self.view_functions[rule.endpoint])(**req.view_args)
  File "app.py", line 110, in metrics
    response=json.dumps(jsonify(data)),
  File "C:\Users\neo\AppData\Local\Programs\Python\Python36\lib\site-packages\flask\json\__init__.py", line 129, in dumps
    rv = _json.dumps(obj, **kwargs)
  File "C:\Users\neo\AppData\Local\Programs\Python\Python36\lib\json\__init__.py", line 238, in dumps
    **kw).encode(obj)
  File "C:\Users\neo\AppData\Local\Programs\Python\Python36\lib\json\encoder.py", line 199, in encode
    chunks = self.iterencode(o, _one_shot=True)
  File "C:\Users\neo\AppData\Local\Programs\Python\Python36\lib\json\encoder.py", line 257, in iterencode
    return _iterencode(o, 0)
  File "C:\Users\neo\AppData\Local\Programs\Python\Python36\lib\site-packages\flask\json\__init__.py", line 56, in default
    return super().default(o)
  File "C:\Users\neo\AppData\Local\Programs\Python\Python36\lib\json\encoder.py", line 180, in default
    o.__class__.__name__)
TypeError: Object of type 'Row' is not JSON serializable
2021-09-06 21:47:38,824 INFO 127.0.0.1 - - [06/Sep/2021 21:47:38] "[35m[1mGET /metrics HTTP/1.1[0m" 500 -
2021-09-06 21:47:49,223 WARNING  * Running on all addresses.
   WARNING: This is a development server. Do not use it in a production deployment.
2021-09-06 21:47:49,224 INFO  * Running on http://192.168.43.247:3111/ (Press CTRL+C to quit)
2021-09-06 21:51:22,246 ERROR Exception on /metrics [GET]
Traceback (most recent call last):
  File "C:\Users\neo\AppData\Local\Programs\Python\Python36\lib\site-packages\flask\app.py", line 2070, in wsgi_app
    response = self.full_dispatch_request()
  File "C:\Users\neo\AppData\Local\Programs\Python\Python36\lib\site-packages\flask\app.py", line 1515, in full_dispatch_request
    rv = self.handle_user_exception(e)
  File "C:\Users\neo\AppData\Local\Programs\Python\Python36\lib\site-packages\flask\app.py", line 1513, in full_dispatch_request
    rv = self.dispatch_request()
  File "C:\Users\neo\AppData\Local\Programs\Python\Python36\lib\site-packages\flask\app.py", line 1499, in dispatch_request
    return self.ensure_sync(self.view_functions[rule.endpoint])(**req.view_args)
  File "app.py", line 110, in metrics
    response=json.dumps(jsonify(data)),
  File "C:\Users\neo\AppData\Local\Programs\Python\Python36\lib\site-packages\flask\json\__init__.py", line 348, in jsonify
    f"{dumps(data, indent=indent, separators=separators)}\n",
  File "C:\Users\neo\AppData\Local\Programs\Python\Python36\lib\site-packages\flask\json\__init__.py", line 129, in dumps
    rv = _json.dumps(obj, **kwargs)
  File "C:\Users\neo\AppData\Local\Programs\Python\Python36\lib\json\__init__.py", line 238, in dumps
    **kw).encode(obj)
  File "C:\Users\neo\AppData\Local\Programs\Python\Python36\lib\json\encoder.py", line 199, in encode
    chunks = self.iterencode(o, _one_shot=True)
  File "C:\Users\neo\AppData\Local\Programs\Python\Python36\lib\json\encoder.py", line 257, in iterencode
    return _iterencode(o, 0)
  File "C:\Users\neo\AppData\Local\Programs\Python\Python36\lib\site-packages\flask\json\__init__.py", line 56, in default
    return super().default(o)
  File "C:\Users\neo\AppData\Local\Programs\Python\Python36\lib\json\encoder.py", line 180, in default
    o.__class__.__name__)
TypeError: Object of type 'Row' is not JSON serializable
2021-09-06 21:51:22,257 INFO 127.0.0.1 - - [06/Sep/2021 21:51:22] "[35m[1mGET /metrics HTTP/1.1[0m" 500 -
2021-09-06 21:51:24,357 ERROR Exception on /metrics [GET]
Traceback (most recent call last):
  File "C:\Users\neo\AppData\Local\Programs\Python\Python36\lib\site-packages\flask\app.py", line 2070, in wsgi_app
    response = self.full_dispatch_request()
  File "C:\Users\neo\AppData\Local\Programs\Python\Python36\lib\site-packages\flask\app.py", line 1515, in full_dispatch_request
    rv = self.handle_user_exception(e)
  File "C:\Users\neo\AppData\Local\Programs\Python\Python36\lib\site-packages\flask\app.py", line 1513, in full_dispatch_request
    rv = self.dispatch_request()
  File "C:\Users\neo\AppData\Local\Programs\Python\Python36\lib\site-packages\flask\app.py", line 1499, in dispatch_request
    return self.ensure_sync(self.view_functions[rule.endpoint])(**req.view_args)
  File "app.py", line 110, in metrics
    response=json.dumps(jsonify(data)),
  File "C:\Users\neo\AppData\Local\Programs\Python\Python36\lib\site-packages\flask\json\__init__.py", line 348, in jsonify
    f"{dumps(data, indent=indent, separators=separators)}\n",
  File "C:\Users\neo\AppData\Local\Programs\Python\Python36\lib\site-packages\flask\json\__init__.py", line 129, in dumps
    rv = _json.dumps(obj, **kwargs)
  File "C:\Users\neo\AppData\Local\Programs\Python\Python36\lib\json\__init__.py", line 238, in dumps
    **kw).encode(obj)
  File "C:\Users\neo\AppData\Local\Programs\Python\Python36\lib\json\encoder.py", line 199, in encode
    chunks = self.iterencode(o, _one_shot=True)
  File "C:\Users\neo\AppData\Local\Programs\Python\Python36\lib\json\encoder.py", line 257, in iterencode
    return _iterencode(o, 0)
  File "C:\Users\neo\AppData\Local\Programs\Python\Python36\lib\site-packages\flask\json\__init__.py", line 56, in default
    return super().default(o)
  File "C:\Users\neo\AppData\Local\Programs\Python\Python36\lib\json\encoder.py", line 180, in default
    o.__class__.__name__)
TypeError: Object of type 'Row' is not JSON serializable
2021-09-06 21:51:24,358 INFO 127.0.0.1 - - [06/Sep/2021 21:51:24] "[35m[1mGET /metrics HTTP/1.1[0m" 500 -
2021-09-06 21:59:29,179 INFO  * Running on http://0.0.0.0:3111/ (Press CTRL+C to quit)
2021-09-06 21:59:32,896 ERROR Exception on /metrics [GET]
Traceback (most recent call last):
  File "C:\Users\neo\AppData\Local\Programs\Python\Python36\lib\site-packages\flask\app.py", line 2446, in wsgi_app
    response = self.full_dispatch_request()
  File "C:\Users\neo\AppData\Local\Programs\Python\Python36\lib\site-packages\flask\app.py", line 1951, in full_dispatch_request
    rv = self.handle_user_exception(e)
  File "C:\Users\neo\AppData\Local\Programs\Python\Python36\lib\site-packages\flask\app.py", line 1820, in handle_user_exception
    reraise(exc_type, exc_value, tb)
  File "C:\Users\neo\AppData\Local\Programs\Python\Python36\lib\site-packages\flask\_compat.py", line 39, in reraise
    raise value
  File "C:\Users\neo\AppData\Local\Programs\Python\Python36\lib\site-packages\flask\app.py", line 1949, in full_dispatch_request
    rv = self.dispatch_request()
  File "C:\Users\neo\AppData\Local\Programs\Python\Python36\lib\site-packages\flask\app.py", line 1935, in dispatch_request
    return self.view_functions[rule.endpoint](**req.view_args)
  File "app.py", line 109, in metrics
    response=json.dumps(jsonify(data)),
  File "C:\Users\neo\AppData\Local\Programs\Python\Python36\lib\site-packages\flask\json\__init__.py", line 370, in jsonify
    dumps(data, indent=indent, separators=separators) + "\n",
  File "C:\Users\neo\AppData\Local\Programs\Python\Python36\lib\site-packages\flask\json\__init__.py", line 211, in dumps
    rv = _json.dumps(obj, **kwargs)
  File "C:\Users\neo\AppData\Local\Programs\Python\Python36\lib\json\__init__.py", line 238, in dumps
    **kw).encode(obj)
  File "C:\Users\neo\AppData\Local\Programs\Python\Python36\lib\json\encoder.py", line 199, in encode
    chunks = self.iterencode(o, _one_shot=True)
  File "C:\Users\neo\AppData\Local\Programs\Python\Python36\lib\json\encoder.py", line 257, in iterencode
    return _iterencode(o, 0)
  File "C:\Users\neo\AppData\Local\Programs\Python\Python36\lib\site-packages\flask\json\__init__.py", line 100, in default
    return _json.JSONEncoder.default(self, o)
  File "C:\Users\neo\AppData\Local\Programs\Python\Python36\lib\json\encoder.py", line 180, in default
    o.__class__.__name__)
TypeError: Object of type 'Row' is not JSON serializable
2021-09-06 21:59:32,922 INFO 127.0.0.1 - - [06/Sep/2021 21:59:32] "GET /metrics HTTP/1.1" 500 -
2021-09-06 22:01:16,861 INFO  * Running on http://0.0.0.0:3111/ (Press CTRL+C to quit)
2021-09-06 22:01:19,072 ERROR Exception on /metrics [GET]
Traceback (most recent call last):
  File "C:\Users\neo\AppData\Local\Programs\Python\Python36\lib\site-packages\flask\app.py", line 2446, in wsgi_app
    response = self.full_dispatch_request()
  File "C:\Users\neo\AppData\Local\Programs\Python\Python36\lib\site-packages\flask\app.py", line 1951, in full_dispatch_request
    rv = self.handle_user_exception(e)
  File "C:\Users\neo\AppData\Local\Programs\Python\Python36\lib\site-packages\flask\app.py", line 1820, in handle_user_exception
    reraise(exc_type, exc_value, tb)
  File "C:\Users\neo\AppData\Local\Programs\Python\Python36\lib\site-packages\flask\_compat.py", line 39, in reraise
    raise value
  File "C:\Users\neo\AppData\Local\Programs\Python\Python36\lib\site-packages\flask\app.py", line 1949, in full_dispatch_request
    rv = self.dispatch_request()
  File "C:\Users\neo\AppData\Local\Programs\Python\Python36\lib\site-packages\flask\app.py", line 1935, in dispatch_request
    return self.view_functions[rule.endpoint](**req.view_args)
  File "app.py", line 105, in metrics
    post_count = jsonify(get_post_count())
  File "C:\Users\neo\AppData\Local\Programs\Python\Python36\lib\site-packages\flask\json\__init__.py", line 370, in jsonify
    dumps(data, indent=indent, separators=separators) + "\n",
  File "C:\Users\neo\AppData\Local\Programs\Python\Python36\lib\site-packages\flask\json\__init__.py", line 211, in dumps
    rv = _json.dumps(obj, **kwargs)
  File "C:\Users\neo\AppData\Local\Programs\Python\Python36\lib\json\__init__.py", line 238, in dumps
    **kw).encode(obj)
  File "C:\Users\neo\AppData\Local\Programs\Python\Python36\lib\json\encoder.py", line 199, in encode
    chunks = self.iterencode(o, _one_shot=True)
  File "C:\Users\neo\AppData\Local\Programs\Python\Python36\lib\json\encoder.py", line 257, in iterencode
    return _iterencode(o, 0)
  File "C:\Users\neo\AppData\Local\Programs\Python\Python36\lib\site-packages\flask\json\__init__.py", line 100, in default
    return _json.JSONEncoder.default(self, o)
  File "C:\Users\neo\AppData\Local\Programs\Python\Python36\lib\json\encoder.py", line 180, in default
    o.__class__.__name__)
TypeError: Object of type 'Row' is not JSON serializable
2021-09-06 22:01:19,085 INFO 127.0.0.1 - - [06/Sep/2021 22:01:19] "GET /metrics HTTP/1.1" 500 -
2021-09-06 22:01:20,888 ERROR Exception on /metrics [GET]
Traceback (most recent call last):
  File "C:\Users\neo\AppData\Local\Programs\Python\Python36\lib\site-packages\flask\app.py", line 2446, in wsgi_app
    response = self.full_dispatch_request()
  File "C:\Users\neo\AppData\Local\Programs\Python\Python36\lib\site-packages\flask\app.py", line 1951, in full_dispatch_request
    rv = self.handle_user_exception(e)
  File "C:\Users\neo\AppData\Local\Programs\Python\Python36\lib\site-packages\flask\app.py", line 1820, in handle_user_exception
    reraise(exc_type, exc_value, tb)
  File "C:\Users\neo\AppData\Local\Programs\Python\Python36\lib\site-packages\flask\_compat.py", line 39, in reraise
    raise value
  File "C:\Users\neo\AppData\Local\Programs\Python\Python36\lib\site-packages\flask\app.py", line 1949, in full_dispatch_request
    rv = self.dispatch_request()
  File "C:\Users\neo\AppData\Local\Programs\Python\Python36\lib\site-packages\flask\app.py", line 1935, in dispatch_request
    return self.view_functions[rule.endpoint](**req.view_args)
  File "app.py", line 105, in metrics
    post_count = jsonify(get_post_count())
  File "C:\Users\neo\AppData\Local\Programs\Python\Python36\lib\site-packages\flask\json\__init__.py", line 370, in jsonify
    dumps(data, indent=indent, separators=separators) + "\n",
  File "C:\Users\neo\AppData\Local\Programs\Python\Python36\lib\site-packages\flask\json\__init__.py", line 211, in dumps
    rv = _json.dumps(obj, **kwargs)
  File "C:\Users\neo\AppData\Local\Programs\Python\Python36\lib\json\__init__.py", line 238, in dumps
    **kw).encode(obj)
  File "C:\Users\neo\AppData\Local\Programs\Python\Python36\lib\json\encoder.py", line 199, in encode
    chunks = self.iterencode(o, _one_shot=True)
  File "C:\Users\neo\AppData\Local\Programs\Python\Python36\lib\json\encoder.py", line 257, in iterencode
    return _iterencode(o, 0)
  File "C:\Users\neo\AppData\Local\Programs\Python\Python36\lib\site-packages\flask\json\__init__.py", line 100, in default
    return _json.JSONEncoder.default(self, o)
  File "C:\Users\neo\AppData\Local\Programs\Python\Python36\lib\json\encoder.py", line 180, in default
    o.__class__.__name__)
TypeError: Object of type 'Row' is not JSON serializable
2021-09-06 22:01:20,890 INFO 127.0.0.1 - - [06/Sep/2021 22:01:20] "GET /metrics HTTP/1.1" 500 -
2021-09-06 22:01:59,895 ERROR Exception on /metrics [GET]
Traceback (most recent call last):
  File "C:\Users\neo\AppData\Local\Programs\Python\Python36\lib\site-packages\flask\app.py", line 2446, in wsgi_app
    response = self.full_dispatch_request()
  File "C:\Users\neo\AppData\Local\Programs\Python\Python36\lib\site-packages\flask\app.py", line 1951, in full_dispatch_request
    rv = self.handle_user_exception(e)
  File "C:\Users\neo\AppData\Local\Programs\Python\Python36\lib\site-packages\flask\app.py", line 1820, in handle_user_exception
    reraise(exc_type, exc_value, tb)
  File "C:\Users\neo\AppData\Local\Programs\Python\Python36\lib\site-packages\flask\_compat.py", line 39, in reraise
    raise value
  File "C:\Users\neo\AppData\Local\Programs\Python\Python36\lib\site-packages\flask\app.py", line 1949, in full_dispatch_request
    rv = self.dispatch_request()
  File "C:\Users\neo\AppData\Local\Programs\Python\Python36\lib\site-packages\flask\app.py", line 1935, in dispatch_request
    return self.view_functions[rule.endpoint](**req.view_args)
  File "app.py", line 105, in metrics
    post_count = jsonify(get_post_count())
  File "C:\Users\neo\AppData\Local\Programs\Python\Python36\lib\site-packages\flask\json\__init__.py", line 370, in jsonify
    dumps(data, indent=indent, separators=separators) + "\n",
  File "C:\Users\neo\AppData\Local\Programs\Python\Python36\lib\site-packages\flask\json\__init__.py", line 211, in dumps
    rv = _json.dumps(obj, **kwargs)
  File "C:\Users\neo\AppData\Local\Programs\Python\Python36\lib\json\__init__.py", line 238, in dumps
    **kw).encode(obj)
  File "C:\Users\neo\AppData\Local\Programs\Python\Python36\lib\json\encoder.py", line 199, in encode
    chunks = self.iterencode(o, _one_shot=True)
  File "C:\Users\neo\AppData\Local\Programs\Python\Python36\lib\json\encoder.py", line 257, in iterencode
    return _iterencode(o, 0)
  File "C:\Users\neo\AppData\Local\Programs\Python\Python36\lib\site-packages\flask\json\__init__.py", line 100, in default
    return _json.JSONEncoder.default(self, o)
  File "C:\Users\neo\AppData\Local\Programs\Python\Python36\lib\json\encoder.py", line 180, in default
    o.__class__.__name__)
TypeError: Object of type 'Row' is not JSON serializable
2021-09-06 22:01:59,896 INFO 127.0.0.1 - - [06/Sep/2021 22:01:59] "GET /metrics HTTP/1.1" 500 -
2021-09-06 22:04:34,849 INFO  * Running on http://0.0.0.0:3111/ (Press CTRL+C to quit)
2021-09-06 22:04:40,067 DEBUG Request /metrics
2021-09-06 22:04:40,068 INFO 127.0.0.1 - - [06/Sep/2021 22:04:40] "GET /metrics HTTP/1.1" 200 -
2021-09-06 22:07:05,165 INFO  * Running on http://0.0.0.0:3111/ (Press CTRL+C to quit)
2021-09-06 22:07:09,556 DEBUG Request /metrics
2021-09-06 22:07:09,558 ERROR Exception on /metrics [GET]
Traceback (most recent call last):
  File "C:\Users\neo\AppData\Local\Programs\Python\Python36\lib\site-packages\flask\app.py", line 2446, in wsgi_app
    response = self.full_dispatch_request()
  File "C:\Users\neo\AppData\Local\Programs\Python\Python36\lib\site-packages\flask\app.py", line 1952, in full_dispatch_request
    return self.finalize_request(rv)
  File "C:\Users\neo\AppData\Local\Programs\Python\Python36\lib\site-packages\flask\app.py", line 1967, in finalize_request
    response = self.make_response(rv)
  File "C:\Users\neo\AppData\Local\Programs\Python\Python36\lib\site-packages\flask\app.py", line 2111, in make_response
    rv = jsonify(rv)
  File "C:\Users\neo\AppData\Local\Programs\Python\Python36\lib\site-packages\flask\json\__init__.py", line 370, in jsonify
    dumps(data, indent=indent, separators=separators) + "\n",
  File "C:\Users\neo\AppData\Local\Programs\Python\Python36\lib\site-packages\flask\json\__init__.py", line 211, in dumps
    rv = _json.dumps(obj, **kwargs)
  File "C:\Users\neo\AppData\Local\Programs\Python\Python36\lib\json\__init__.py", line 238, in dumps
    **kw).encode(obj)
  File "C:\Users\neo\AppData\Local\Programs\Python\Python36\lib\json\encoder.py", line 199, in encode
    chunks = self.iterencode(o, _one_shot=True)
  File "C:\Users\neo\AppData\Local\Programs\Python\Python36\lib\json\encoder.py", line 257, in iterencode
    return _iterencode(o, 0)
  File "C:\Users\neo\AppData\Local\Programs\Python\Python36\lib\site-packages\flask\json\__init__.py", line 100, in default
    return _json.JSONEncoder.default(self, o)
  File "C:\Users\neo\AppData\Local\Programs\Python\Python36\lib\json\encoder.py", line 180, in default
    o.__class__.__name__)
TypeError: Object of type 'Row' is not JSON serializable
2021-09-06 22:07:09,573 INFO 127.0.0.1 - - [06/Sep/2021 22:07:09] "GET /metrics HTTP/1.1" 500 -
2021-09-06 22:08:50,277 INFO  * Running on http://0.0.0.0:3111/ (Press CTRL+C to quit)
2021-09-06 22:08:51,611 ERROR Exception on /metrics [GET]
Traceback (most recent call last):
  File "C:\Users\neo\AppData\Local\Programs\Python\Python36\lib\site-packages\flask\app.py", line 2446, in wsgi_app
    response = self.full_dispatch_request()
  File "C:\Users\neo\AppData\Local\Programs\Python\Python36\lib\site-packages\flask\app.py", line 1951, in full_dispatch_request
    rv = self.handle_user_exception(e)
  File "C:\Users\neo\AppData\Local\Programs\Python\Python36\lib\site-packages\flask\app.py", line 1820, in handle_user_exception
    reraise(exc_type, exc_value, tb)
  File "C:\Users\neo\AppData\Local\Programs\Python\Python36\lib\site-packages\flask\_compat.py", line 39, in reraise
    raise value
  File "C:\Users\neo\AppData\Local\Programs\Python\Python36\lib\site-packages\flask\app.py", line 1949, in full_dispatch_request
    rv = self.dispatch_request()
  File "C:\Users\neo\AppData\Local\Programs\Python\Python36\lib\site-packages\flask\app.py", line 1935, in dispatch_request
    return self.view_functions[rule.endpoint](**req.view_args)
  File "app.py", line 109, in metrics
    response=json.dumps(data),
  File "C:\Users\neo\AppData\Local\Programs\Python\Python36\lib\site-packages\flask\json\__init__.py", line 211, in dumps
    rv = _json.dumps(obj, **kwargs)
  File "C:\Users\neo\AppData\Local\Programs\Python\Python36\lib\json\__init__.py", line 238, in dumps
    **kw).encode(obj)
  File "C:\Users\neo\AppData\Local\Programs\Python\Python36\lib\json\encoder.py", line 199, in encode
    chunks = self.iterencode(o, _one_shot=True)
  File "C:\Users\neo\AppData\Local\Programs\Python\Python36\lib\json\encoder.py", line 257, in iterencode
    return _iterencode(o, 0)
  File "C:\Users\neo\AppData\Local\Programs\Python\Python36\lib\site-packages\flask\json\__init__.py", line 100, in default
    return _json.JSONEncoder.default(self, o)
  File "C:\Users\neo\AppData\Local\Programs\Python\Python36\lib\json\encoder.py", line 180, in default
    o.__class__.__name__)
TypeError: Object of type 'Row' is not JSON serializable
2021-09-06 22:08:51,623 INFO 127.0.0.1 - - [06/Sep/2021 22:08:51] "GET /metrics HTTP/1.1" 500 -
2021-09-06 22:14:12,223 INFO  * Running on http://0.0.0.0:3111/ (Press CTRL+C to quit)
2021-09-06 22:14:15,860 ERROR Exception on /metrics [GET]
Traceback (most recent call last):
  File "C:\Users\neo\AppData\Local\Programs\Python\Python36\lib\site-packages\flask\app.py", line 2446, in wsgi_app
    response = self.full_dispatch_request()
  File "C:\Users\neo\AppData\Local\Programs\Python\Python36\lib\site-packages\flask\app.py", line 1951, in full_dispatch_request
    rv = self.handle_user_exception(e)
  File "C:\Users\neo\AppData\Local\Programs\Python\Python36\lib\site-packages\flask\app.py", line 1820, in handle_user_exception
    reraise(exc_type, exc_value, tb)
  File "C:\Users\neo\AppData\Local\Programs\Python\Python36\lib\site-packages\flask\_compat.py", line 39, in reraise
    raise value
  File "C:\Users\neo\AppData\Local\Programs\Python\Python36\lib\site-packages\flask\app.py", line 1949, in full_dispatch_request
    rv = self.dispatch_request()
  File "C:\Users\neo\AppData\Local\Programs\Python\Python36\lib\site-packages\flask\app.py", line 1935, in dispatch_request
    return self.view_functions[rule.endpoint](**req.view_args)
  File "app.py", line 108, in metrics
    post_count = get_post_count()
  File "app.py", line 40, in get_post_count
    data.append[list(row)]
TypeError: 'int' object is not iterable
2021-09-06 22:14:15,880 INFO 127.0.0.1 - - [06/Sep/2021 22:14:15] "GET /metrics HTTP/1.1" 500 -
2021-09-06 22:16:30,213 INFO  * Running on http://0.0.0.0:3111/ (Press CTRL+C to quit)
2021-09-06 22:16:31,451 ERROR Exception on /metrics [GET]
Traceback (most recent call last):
  File "C:\Users\neo\AppData\Local\Programs\Python\Python36\lib\site-packages\flask\app.py", line 2446, in wsgi_app
    response = self.full_dispatch_request()
  File "C:\Users\neo\AppData\Local\Programs\Python\Python36\lib\site-packages\flask\app.py", line 1951, in full_dispatch_request
    rv = self.handle_user_exception(e)
  File "C:\Users\neo\AppData\Local\Programs\Python\Python36\lib\site-packages\flask\app.py", line 1820, in handle_user_exception
    reraise(exc_type, exc_value, tb)
  File "C:\Users\neo\AppData\Local\Programs\Python\Python36\lib\site-packages\flask\_compat.py", line 39, in reraise
    raise value
  File "C:\Users\neo\AppData\Local\Programs\Python\Python36\lib\site-packages\flask\app.py", line 1949, in full_dispatch_request
    rv = self.dispatch_request()
  File "C:\Users\neo\AppData\Local\Programs\Python\Python36\lib\site-packages\flask\app.py", line 1935, in dispatch_request
    return self.view_functions[rule.endpoint](**req.view_args)
  File "app.py", line 110, in metrics
    response=json.dumps(data),
  File "C:\Users\neo\AppData\Local\Programs\Python\Python36\lib\site-packages\flask\json\__init__.py", line 211, in dumps
    rv = _json.dumps(obj, **kwargs)
  File "C:\Users\neo\AppData\Local\Programs\Python\Python36\lib\json\__init__.py", line 238, in dumps
    **kw).encode(obj)
  File "C:\Users\neo\AppData\Local\Programs\Python\Python36\lib\json\encoder.py", line 199, in encode
    chunks = self.iterencode(o, _one_shot=True)
  File "C:\Users\neo\AppData\Local\Programs\Python\Python36\lib\json\encoder.py", line 257, in iterencode
    return _iterencode(o, 0)
  File "C:\Users\neo\AppData\Local\Programs\Python\Python36\lib\site-packages\flask\json\__init__.py", line 100, in default
    return _json.JSONEncoder.default(self, o)
  File "C:\Users\neo\AppData\Local\Programs\Python\Python36\lib\json\encoder.py", line 180, in default
    o.__class__.__name__)
TypeError: Object of type 'Row' is not JSON serializable
2021-09-06 22:16:31,463 INFO 127.0.0.1 - - [06/Sep/2021 22:16:31] "GET /metrics HTTP/1.1" 500 -
2021-09-06 22:17:58,310 INFO 127.0.0.1 - - [06/Sep/2021 22:17:58] "GET /status HTTP/1.1" 404 -
2021-09-06 22:18:18,693 DEBUG Request /status
2021-09-06 22:18:18,694 INFO 127.0.0.1 - - [06/Sep/2021 22:18:18] "GET /healthz HTTP/1.1" 200 -
2021-09-06 22:19:01,555 INFO  * Running on http://0.0.0.0:3111/ (Press CTRL+C to quit)
2021-09-06 22:19:08,973 DEBUG Request /metrics
2021-09-06 22:19:08,974 INFO 127.0.0.1 - - [06/Sep/2021 22:19:08] "GET /metrics HTTP/1.1" 200 -
2021-09-06 22:21:47,038 INFO  * Running on http://0.0.0.0:3111/ (Press CTRL+C to quit)
2021-09-06 22:21:59,810 ERROR Exception on /metrics [GET]
Traceback (most recent call last):
  File "C:\Users\neo\AppData\Local\Programs\Python\Python36\lib\site-packages\flask\app.py", line 2446, in wsgi_app
    response = self.full_dispatch_request()
  File "C:\Users\neo\AppData\Local\Programs\Python\Python36\lib\site-packages\flask\app.py", line 1951, in full_dispatch_request
    rv = self.handle_user_exception(e)
  File "C:\Users\neo\AppData\Local\Programs\Python\Python36\lib\site-packages\flask\app.py", line 1820, in handle_user_exception
    reraise(exc_type, exc_value, tb)
  File "C:\Users\neo\AppData\Local\Programs\Python\Python36\lib\site-packages\flask\_compat.py", line 39, in reraise
    raise value
  File "C:\Users\neo\AppData\Local\Programs\Python\Python36\lib\site-packages\flask\app.py", line 1949, in full_dispatch_request
    rv = self.dispatch_request()
  File "C:\Users\neo\AppData\Local\Programs\Python\Python36\lib\site-packages\flask\app.py", line 1935, in dispatch_request
    return self.view_functions[rule.endpoint](**req.view_args)
  File "app.py", line 105, in metrics
    post_count = get_post_count()
  File "app.py", line 38, in get_post_count
    return int(posts)
TypeError: int() argument must be a string, a bytes-like object or a number, not 'sqlite3.Row'
2021-09-06 22:21:59,814 INFO 127.0.0.1 - - [06/Sep/2021 22:21:59] "GET /metrics HTTP/1.1" 500 -
2021-09-06 22:26:11,603 INFO  * Running on http://0.0.0.0:3111/ (Press CTRL+C to quit)
2021-09-06 22:26:23,634 ERROR Exception on /metrics [GET]
Traceback (most recent call last):
  File "C:\Users\neo\AppData\Local\Programs\Python\Python36\lib\site-packages\flask\app.py", line 2446, in wsgi_app
    response = self.full_dispatch_request()
  File "C:\Users\neo\AppData\Local\Programs\Python\Python36\lib\site-packages\flask\app.py", line 1951, in full_dispatch_request
    rv = self.handle_user_exception(e)
  File "C:\Users\neo\AppData\Local\Programs\Python\Python36\lib\site-packages\flask\app.py", line 1820, in handle_user_exception
    reraise(exc_type, exc_value, tb)
  File "C:\Users\neo\AppData\Local\Programs\Python\Python36\lib\site-packages\flask\_compat.py", line 39, in reraise
    raise value
  File "C:\Users\neo\AppData\Local\Programs\Python\Python36\lib\site-packages\flask\app.py", line 1949, in full_dispatch_request
    rv = self.dispatch_request()
  File "C:\Users\neo\AppData\Local\Programs\Python\Python36\lib\site-packages\flask\app.py", line 1935, in dispatch_request
    return self.view_functions[rule.endpoint](**req.view_args)
  File "app.py", line 106, in metrics
    data = {"db_connection_count": connections, "post_count": get_post_count()}
  File "app.py", line 38, in get_post_count
    return posts['count']
IndexError: No item with that key
2021-09-06 22:26:23,640 INFO 127.0.0.1 - - [06/Sep/2021 22:26:23] "GET /metrics HTTP/1.1" 500 -
2021-09-06 22:26:25,502 ERROR Exception on /metrics [GET]
Traceback (most recent call last):
  File "C:\Users\neo\AppData\Local\Programs\Python\Python36\lib\site-packages\flask\app.py", line 2446, in wsgi_app
    response = self.full_dispatch_request()
  File "C:\Users\neo\AppData\Local\Programs\Python\Python36\lib\site-packages\flask\app.py", line 1951, in full_dispatch_request
    rv = self.handle_user_exception(e)
  File "C:\Users\neo\AppData\Local\Programs\Python\Python36\lib\site-packages\flask\app.py", line 1820, in handle_user_exception
    reraise(exc_type, exc_value, tb)
  File "C:\Users\neo\AppData\Local\Programs\Python\Python36\lib\site-packages\flask\_compat.py", line 39, in reraise
    raise value
  File "C:\Users\neo\AppData\Local\Programs\Python\Python36\lib\site-packages\flask\app.py", line 1949, in full_dispatch_request
    rv = self.dispatch_request()
  File "C:\Users\neo\AppData\Local\Programs\Python\Python36\lib\site-packages\flask\app.py", line 1935, in dispatch_request
    return self.view_functions[rule.endpoint](**req.view_args)
  File "app.py", line 106, in metrics
    data = {"db_connection_count": connections, "post_count": get_post_count()}
  File "app.py", line 38, in get_post_count
    return posts['count']
IndexError: No item with that key
2021-09-06 22:26:25,504 INFO 127.0.0.1 - - [06/Sep/2021 22:26:25] "GET /metrics HTTP/1.1" 500 -
2021-09-06 22:27:39,165 INFO  * Running on http://0.0.0.0:3111/ (Press CTRL+C to quit)
2021-09-06 22:27:41,247 ERROR Exception on /metrics [GET]
Traceback (most recent call last):
  File "C:\Users\neo\AppData\Local\Programs\Python\Python36\lib\site-packages\flask\app.py", line 2446, in wsgi_app
    response = self.full_dispatch_request()
  File "C:\Users\neo\AppData\Local\Programs\Python\Python36\lib\site-packages\flask\app.py", line 1951, in full_dispatch_request
    rv = self.handle_user_exception(e)
  File "C:\Users\neo\AppData\Local\Programs\Python\Python36\lib\site-packages\flask\app.py", line 1820, in handle_user_exception
    reraise(exc_type, exc_value, tb)
  File "C:\Users\neo\AppData\Local\Programs\Python\Python36\lib\site-packages\flask\_compat.py", line 39, in reraise
    raise value
  File "C:\Users\neo\AppData\Local\Programs\Python\Python36\lib\site-packages\flask\app.py", line 1949, in full_dispatch_request
    rv = self.dispatch_request()
  File "C:\Users\neo\AppData\Local\Programs\Python\Python36\lib\site-packages\flask\app.py", line 1935, in dispatch_request
    return self.view_functions[rule.endpoint](**req.view_args)
  File "app.py", line 107, in metrics
    data = {"db_connection_count": connections, "post_count": get_post_count()}
  File "app.py", line 38, in get_post_count
    app.logger.info("posts: " + posts)
TypeError: must be str, not sqlite3.Row
2021-09-06 22:27:41,254 INFO 127.0.0.1 - - [06/Sep/2021 22:27:41] "GET /metrics HTTP/1.1" 500 -
2021-09-06 22:29:55,998 INFO  * Running on http://0.0.0.0:3111/ (Press CTRL+C to quit)
2021-09-06 22:30:07,277 ERROR Exception on /metrics [GET]
Traceback (most recent call last):
  File "C:\Users\neo\AppData\Local\Programs\Python\Python36\lib\site-packages\flask\app.py", line 2446, in wsgi_app
    response = self.full_dispatch_request()
  File "C:\Users\neo\AppData\Local\Programs\Python\Python36\lib\site-packages\flask\app.py", line 1951, in full_dispatch_request
    rv = self.handle_user_exception(e)
  File "C:\Users\neo\AppData\Local\Programs\Python\Python36\lib\site-packages\flask\app.py", line 1820, in handle_user_exception
    reraise(exc_type, exc_value, tb)
  File "C:\Users\neo\AppData\Local\Programs\Python\Python36\lib\site-packages\flask\_compat.py", line 39, in reraise
    raise value
  File "C:\Users\neo\AppData\Local\Programs\Python\Python36\lib\site-packages\flask\app.py", line 1949, in full_dispatch_request
    rv = self.dispatch_request()
  File "C:\Users\neo\AppData\Local\Programs\Python\Python36\lib\site-packages\flask\app.py", line 1935, in dispatch_request
    return self.view_functions[rule.endpoint](**req.view_args)
  File "app.py", line 107, in metrics
    data = {"db_connection_count": connections, "post_count": get_post_count()}
  File "app.py", line 38, in get_post_count
    app.logger.info("posts: " + posts)
TypeError: must be str, not sqlite3.Row
2021-09-06 22:30:07,287 INFO 127.0.0.1 - - [06/Sep/2021 22:30:07] "GET /metrics HTTP/1.1" 500 -
2021-09-06 22:30:29,062 INFO  * Running on http://0.0.0.0:3111/ (Press CTRL+C to quit)
2021-09-06 22:30:30,354 ERROR Exception on /metrics [GET]
Traceback (most recent call last):
  File "C:\Users\neo\AppData\Local\Programs\Python\Python36\lib\site-packages\flask\app.py", line 2446, in wsgi_app
    response = self.full_dispatch_request()
  File "C:\Users\neo\AppData\Local\Programs\Python\Python36\lib\site-packages\flask\app.py", line 1951, in full_dispatch_request
    rv = self.handle_user_exception(e)
  File "C:\Users\neo\AppData\Local\Programs\Python\Python36\lib\site-packages\flask\app.py", line 1820, in handle_user_exception
    reraise(exc_type, exc_value, tb)
  File "C:\Users\neo\AppData\Local\Programs\Python\Python36\lib\site-packages\flask\_compat.py", line 39, in reraise
    raise value
  File "C:\Users\neo\AppData\Local\Programs\Python\Python36\lib\site-packages\flask\app.py", line 1949, in full_dispatch_request
    rv = self.dispatch_request()
  File "C:\Users\neo\AppData\Local\Programs\Python\Python36\lib\site-packages\flask\app.py", line 1935, in dispatch_request
    return self.view_functions[rule.endpoint](**req.view_args)
  File "app.py", line 107, in metrics
    data = {"db_connection_count": connections, "post_count": get_post_count()}
  File "app.py", line 38, in get_post_count
    app.logger.info("posts: " + posts[0])
TypeError: must be str, not int
2021-09-06 22:30:30,360 INFO 127.0.0.1 - - [06/Sep/2021 22:30:30] "GET /metrics HTTP/1.1" 500 -
2021-09-06 22:31:08,687 INFO  * Running on http://0.0.0.0:3111/ (Press CTRL+C to quit)
2021-09-06 22:31:10,226 DEBUG Request /metrics
2021-09-06 22:31:10,227 INFO 127.0.0.1 - - [06/Sep/2021 22:31:10] "GET /metrics HTTP/1.1" 200 -
2021-09-06 22:31:53,392 INFO 127.0.0.1 - - [06/Sep/2021 22:31:53] "GET / HTTP/1.1" 200 -
2021-09-06 22:31:53,422 INFO 127.0.0.1 - - [06/Sep/2021 22:31:53] "GET /static/css/main.css HTTP/1.1" 304 -
2021-09-06 22:31:57,478 INFO my first post
2021-09-06 22:31:57,489 INFO 127.0.0.1 - - [06/Sep/2021 22:31:57] "GET /7 HTTP/1.1" 200 -
2021-09-06 22:40:00,013 INFO  * Running on http://0.0.0.0:3111/ (Press CTRL+C to quit)
2021-09-06 22:40:03,317 INFO my first post
2021-09-06 22:40:03,396 INFO 127.0.0.1 - - [06/Sep/2021 22:40:03] "GET /7 HTTP/1.1" 200 -
2021-09-06 22:40:20,305 DEBUG Request /metrics
2021-09-06 22:40:20,306 INFO 127.0.0.1 - - [06/Sep/2021 22:40:20] "GET /metrics HTTP/1.1" 200 -
2021-09-08 19:17:26,150 INFO _log(122)  * Running on http://0.0.0.0:3111/ (Press CTRL+C to quit)
2021-09-08 19:17:30,570 DEBUG metrics(113) Request /metrics
2021-09-08 19:17:30,572 INFO _log(122) 127.0.0.1 - - [08/Sep/2021 19:17:30] "GET /metrics HTTP/1.1" 200 -
